Workbook

Sheet 📊 Dashboard
A1: DASHBOARD FINANCIERO — AGENCIA DE INTELIGENCIA ARTIFICIAL MX | Q1: Mes | R1: MRR (MXN) | S1: Año | T1: Margen EBITDA
A2: Plan de Negocios 2025–2029 | Tipo de cambio: $17.50 MXN/USD | Escenario: Base Realista | Q2: =A18 -> Ene 2025 | R2: =H18 -> 7875 | S2: =A10 -> Año 1 (2025) | T2: =H10 -> 0.91
Q3: =A19 -> 45689 | R3: =H19 -> 7875 | S3: =A11 -> Año 2 (2026) | T3: =H11 -> 0.81
A4: 💰 INGRESOS AÑO 1 | C4: 📈 INGRESOS AÑO 5 | E4: 🎯 META MRR | G4: 📅 MES BREAK-EVEN | I4: 👥 CLIENTES AÑO 5 | K4: 💹 MARGEN EBITDA Y5 | Q4: =A20 -> 45717 | R4: =H20 -> 15750 | S4: =A12 -> Año 3 (2027) | T4: =H12 -> 0.79
A5: ='10. Proyecciones Financieras'!E52 -> 1013250 | C5: ='10. Proyecciones Financieras'!E56 -> 13881000 | E5: ='10. Proyecciones Financieras'!B63 -> ~14 clientes activos con retainer | G5: Mes 15-18 | I5: ='10. Proyecciones Financieras'!B56 -> 75 | K5: ='10. Proyecciones Financieras'!H56 -> 0.73 | Q5: =A21 -> Abr 2025 | R5: =H21 -> 23625 | S5: =A13 -> Año 4 (2028) | T5: =H13 -> 0.76
A6: Total ingresos (MXN) | C6: Total ingresos (MXN) | E6: $175,000 MXN/mes | G6: Escenario base | I6: Clientes activos (prom.) | K6: EBITDA / Ingresos | Q6: =A22 -> 45778 | R6: =H22 -> 31500 | S6: =A14 -> Año 5 (2029) | T6: =H14 -> 0.73
Q7: =A23 -> 45809 | R7: =H23 -> 39375
A8: RESUMEN FINANCIERO ANUAL | J8: COSTOS MENSUALES ESTIMADOS POR AÑO (MXN) | Q8: =A24 -> 45839 | R8: =H24 -> 55125
A9: Año | B9: Clientes | C9: Ing. Proyectos | D9: Ing. Recurrente | E9: Total Ingresos | F9: Costos Totales | G9: EBITDA | H9: Margen | J9: Categoría | K9: Año 1 | L9: Año 2 | M9: Año 3 | N9: Año 4 | O9: Año 5 | Q9: =A25 -> Ago 2025 | R9: =H25 -> 63000
A10: ='10. Proyecciones Financieras'!A52 -> Año 1 (2025) | B10: ='10. Proyecciones Financieras'!B52 -> 5 | C10: ='10. Proyecciones Financieras'!C52 -> 682500 | D10: ='10. Proyecciones Financieras'!D52 -> 330750 | E10: ='10. Proyecciones Financieras'!E52 -> 1013250 | F10: ='10. Proyecciones Financieras'!F52 -> 88200 | G10: ='10. Proyecciones Financieras'!G52 -> 925050 | H10: ='10. Proyecciones Financieras'!H52 -> 0.91 | J10: ='10. Proyecciones Financieras'!A41 -> Herramientas IA (APIs) | K10: ='10. Proyecciones Financieras'!C41 -> 3500 | L10: ='10. Proyecciones Financieras'!D41 -> 7000 | M10: ='10. Proyecciones Financieras'!E41 -> 12250 | N10: ='10. Proyecciones Financieras'!F41 -> 21000 | O10: ='10. Proyecciones Financieras'!G41 -> 35000 | Q10: =A26 -> 45901 | R10: =H26 -> 78750
A11: ='10. Proyecciones Financieras'!A53 -> Año 2 (2026) | B11: ='10. Proyecciones Financieras'!B53 -> 15 | C11: ='10. Proyecciones Financieras'!C53 -> 1470000 | D11: ='10. Proyecciones Financieras'!D53 -> 1323000 | E11: ='10. Proyecciones Financieras'!E53 -> 2793000 | F11: ='10. Proyecciones Financieras'!F53 -> 540330 | G11: ='10. Proyecciones Financieras'!G53 -> 2252670 | H11: ='10. Proyecciones Financieras'!H53 -> 0.81 | J11: ='10. Proyecciones Financieras'!A42 -> Herramientas operativas | K11: ='10. Proyecciones Financieras'!C42 -> 875 | L11: ='10. Proyecciones Financieras'!D42 -> 1750 | M11: ='10. Proyecciones Financieras'!E42 -> 3500 | N11: ='10. Proyecciones Financieras'!F42 -> 6125 | O11: ='10. Proyecciones Financieras'!G42 -> 8750 | Q11: =A27 -> 45931 | R11: =H27 -> 86625
A12: ='10. Proyecciones Financieras'!A54 -> Año 3 (2027) | B12: ='10. Proyecciones Financieras'!B54 -> 30 | C12: ='10. Proyecciones Financieras'!C54 -> 2205000 | D12: ='10. Proyecciones Financieras'!D54 -> 3402000 | E12: ='10. Proyecciones Financieras'!E54 -> 5607000 | F12: ='10. Proyecciones Financieras'!F54 -> 1159830 | G12: ='10. Proyecciones Financieras'!G54 -> 4447170 | H12: ='10. Proyecciones Financieras'!H54 -> 0.79 | J12: ='10. Proyecciones Financieras'!A43 -> Marketing digital | K12: ='10. Proyecciones Financieras'!C43 -> 0 | L12: ='10. Proyecciones Financieras'!D43 -> 3500 | M12: ='10. Proyecciones Financieras'!E43 -> 8750 | N12: ='10. Proyecciones Financieras'!F43 -> 17500 | O12: ='10. Proyecciones Financieras'!G43 -> 35000 | Q12: =A28 -> 45962 | R12: =H28 -> 94500
A13: ='10. Proyecciones Financieras'!A55 -> Año 4 (2028) | B13: ='10. Proyecciones Financieras'!B55 -> 50 | C13: ='10. Proyecciones Financieras'!C55 -> 2940000 | D13: ='10. Proyecciones Financieras'!D55 -> 6237000 | E13: ='10. Proyecciones Financieras'!E55 -> 9177000 | F13: ='10. Proyecciones Financieras'!F55 -> 2216130 | G13: ='10. Proyecciones Financieras'!G55 -> 6960870 | H13: ='10. Proyecciones Financieras'!H55 -> 0.76 | J13: ='10. Proyecciones Financieras'!A44 -> Nómina / Freelancers | K13: ='10. Proyecciones Financieras'!C44 -> 0 | L13: ='10. Proyecciones Financieras'!D44 -> 26250 | M13: ='10. Proyecciones Financieras'!E44 -> 61250 | N13: ='10. Proyecciones Financieras'!F44 -> 122500 | O13: ='10. Proyecciones Financieras'!G44 -> 210000 | Q13: =A29 -> Dic 2025 | R13: =H29 -> 110250
A14: ='10. Proyecciones Financieras'!A56 -> Año 5 (2029) | B14: ='10. Proyecciones Financieras'!B56 -> 75 | C14: ='10. Proyecciones Financieras'!C56 -> 3675000 | D14: ='10. Proyecciones Financieras'!D56 -> 10206000 | E14: ='10. Proyecciones Financieras'!E56 -> 13881000 | F14: ='10. Proyecciones Financieras'!F56 -> 3792600 | G14: ='10. Proyecciones Financieras'!G56 -> 10088400 | H14: ='10. Proyecciones Financieras'!H56 -> 0.73 | J14: ='10. Proyecciones Financieras'!A45 -> Contabilidad / Legal | K14: ='10. Proyecciones Financieras'!C45 -> 1750 | L14: ='10. Proyecciones Financieras'!D45 -> 2625 | M14: ='10. Proyecciones Financieras'!E45 -> 3500 | N14: ='10. Proyecciones Financieras'!F45 -> 5250 | O14: ='10. Proyecciones Financieras'!G45 -> 7000 | Q14: =A30 -> Ene 2026 | R14: =H30 -> 126000
J15: ='10. Proyecciones Financieras'!A46 -> Capacitación técnica | K15: ='10. Proyecciones Financieras'!C46 -> 875 | L15: ='10. Proyecciones Financieras'!D46 -> 1750 | M15: ='10. Proyecciones Financieras'!E46 -> 2625 | N15: ='10. Proyecciones Financieras'!F46 -> 3500 | O15: ='10. Proyecciones Financieras'!G46 -> 5250 | Q15: =A31 -> 46054 | R15: =H31 -> 133875
A16: PROYECCIÓN MENSUAL (24 MESES) | J16: ='10. Proyecciones Financieras'!A47 -> Contingencias (5%) | K16: ='10. Proyecciones Financieras'!C47 -> 350 | L16: ='10. Proyecciones Financieras'!D47 -> 2152.5 | M16: ='10. Proyecciones Financieras'!E47 -> 4777.5 | N16: ='10. Proyecciones Financieras'!F47 -> 8802.5 | O16: ='10. Proyecciones Financieras'!G47 -> 15050 | Q16: =A32 -> 46082 | R16: =H32 -> 157500
A17: Mes | B17: Mes # | C17: Clientes nuevos | D17: Clientes activos | E17: Ing. Proyectos | F17: Ing. Recurrente | G17: Total Ingresos | H17: MRR | J17: ='10. Proyecciones Financieras'!A48 -> TOTAL COSTOS MENSUALES | K17: ='10. Proyecciones Financieras'!C48 -> 7350 | L17: ='10. Proyecciones Financieras'!D48 -> 45027.5 | M17: ='10. Proyecciones Financieras'!E48 -> 96652.5 | N17: ='10. Proyecciones Financieras'!F48 -> 184677.5 | O17: ='10. Proyecciones Financieras'!G48 -> 316050 | Q17: =A33 -> Abr 2026 | R17: =H33 -> 173250
A18: ='10. Proyecciones Financieras'!A14 -> Ene 2025 | B18: ='10. Proyecciones Financieras'!B14 -> 1 | C18: ='10. Proyecciones Financieras'!C14 -> 1 | D18: ='10. Proyecciones Financieras'!D14 -> 1 | E18: ='10. Proyecciones Financieras'!E14 -> 43750 | F18: ='10. Proyecciones Financieras'!F14 -> 7875 | G18: ='10. Proyecciones Financieras'!G14 -> 51625 | H18: ='10. Proyecciones Financieras'!H14 -> 7875 | Q18: =A34 -> 46143 | R18: =H34 -> 196875
A19: ='10. Proyecciones Financieras'!A15 -> 45689 | B19: ='10. Proyecciones Financieras'!B15 -> 2 | C19: ='10. Proyecciones Financieras'!C15 -> 1 | D19: ='10. Proyecciones Financieras'!D15 -> 2 | E19: ='10. Proyecciones Financieras'!E15 -> 43750 | F19: ='10. Proyecciones Financieras'!F15 -> 7875 | G19: ='10. Proyecciones Financieras'!G15 -> 51625 | H19: ='10. Proyecciones Financieras'!H15 -> 7875 | Q19: =A35 -> 46174 | R19: =H35 -> 212625
A20: ='10. Proyecciones Financieras'!A16 -> 45717 | B20: ='10. Proyecciones Financieras'!B16 -> 3 | C20: ='10. Proyecciones Financieras'!C16 -> 1 | D20: ='10. Proyecciones Financieras'!D16 -> 3 | E20: ='10. Proyecciones Financieras'!E16 -> 43750 | F20: ='10. Proyecciones Financieras'!F16 -> 15750 | G20: ='10. Proyecciones Financieras'!G16 -> 59500 | H20: ='10. Proyecciones Financieras'!H16 -> 15750 | Q20: =A36 -> 46204 | R20: =H36 -> 228375
A21: ='10. Proyecciones Financieras'!A17 -> Abr 2025 | B21: ='10. Proyecciones Financieras'!B17 -> 4 | C21: ='10. Proyecciones Financieras'!C17 -> 2 | D21: ='10. Proyecciones Financieras'!D17 -> 5 | E21: ='10. Proyecciones Financieras'!E17 -> 87500 | F21: ='10. Proyecciones Financieras'!F17 -> 23625 | G21: ='10. Proyecciones Financieras'!G17 -> 111125 | H21: ='10. Proyecciones Financieras'!H17 -> 23625 | Q21: =A37 -> Ago 2026 | R21: =H37 -> 252000
A22: ='10. Proyecciones Financieras'!A18 -> 45778 | B22: ='10. Proyecciones Financieras'!B18 -> 5 | C22: ='10. Proyecciones Financieras'!C18 -> 2 | D22: ='10. Proyecciones Financieras'!D18 -> 7 | E22: ='10. Proyecciones Financieras'!E18 -> 87500 | F22: ='10. Proyecciones Financieras'!F18 -> 31500 | G22: ='10. Proyecciones Financieras'!G18 -> 119000 | H22: ='10. Proyecciones Financieras'!H18 -> 31500 | Q22: =A38 -> 46266 | R22: =H38 -> 275625
A23: ='10. Proyecciones Financieras'!A19 -> 45809 | B23: ='10. Proyecciones Financieras'!B19 -> 6 | C23: ='10. Proyecciones Financieras'!C19 -> 2 | D23: ='10. Proyecciones Financieras'!D19 -> 9 | E23: ='10. Proyecciones Financieras'!E19 -> 87500 | F23: ='10. Proyecciones Financieras'!F19 -> 39375 | G23: ='10. Proyecciones Financieras'!G19 -> 126875 | H23: ='10. Proyecciones Financieras'!H19 -> 39375 | Q23: =A39 -> 46296 | R23: =H39 -> 299250
A24: ='10. Proyecciones Financieras'!A20 -> 45839 | B24: ='10. Proyecciones Financieras'!B20 -> 7 | C24: ='10. Proyecciones Financieras'!C20 -> 2 | D24: ='10. Proyecciones Financieras'!D20 -> 11 | E24: ='10. Proyecciones Financieras'!E20 -> 87500 | F24: ='10. Proyecciones Financieras'!F20 -> 55125 | G24: ='10. Proyecciones Financieras'!G20 -> 142625 | H24: ='10. Proyecciones Financieras'!H20 -> 55125 | Q24: =A40 -> 46327 | R24: =H40 -> 322875
A25: ='10. Proyecciones Financieras'!A21 -> Ago 2025 | B25: ='10. Proyecciones Financieras'!B21 -> 8 | C25: ='10. Proyecciones Financieras'!C21 -> 3 | D25: ='10. Proyecciones Financieras'!D21 -> 14 | E25: ='10. Proyecciones Financieras'!E21 -> 131250 | F25: ='10. Proyecciones Financieras'!F21 -> 63000 | G25: ='10. Proyecciones Financieras'!G21 -> 194250 | H25: ='10. Proyecciones Financieras'!H21 -> 63000 | Q25: =A41 -> Dic 2026 | R25: =H41 -> 346500
A26: ='10. Proyecciones Financieras'!A22 -> 45901 | B26: ='10. Proyecciones Financieras'!B22 -> 9 | C26: ='10. Proyecciones Financieras'!C22 -> 3 | D26: ='10. Proyecciones Financieras'!D22 -> 16 | E26: ='10. Proyecciones Financieras'!E22 -> 131250 | F26: ='10. Proyecciones Financieras'!F22 -> 78750 | G26: ='10. Proyecciones Financieras'!G22 -> 210000 | H26: ='10. Proyecciones Financieras'!H22 -> 78750
A27: ='10. Proyecciones Financieras'!A23 -> 45931 | B27: ='10. Proyecciones Financieras'!B23 -> 10 | C27: ='10. Proyecciones Financieras'!C23 -> 3 | D27: ='10. Proyecciones Financieras'!D23 -> 18 | E27: ='10. Proyecciones Financieras'!E23 -> 131250 | F27: ='10. Proyecciones Financieras'!F23 -> 86625 | G27: ='10. Proyecciones Financieras'!G23 -> 217875 | H27: ='10. Proyecciones Financieras'!H23 -> 86625
A28: ='10. Proyecciones Financieras'!A24 -> 45962 | B28: ='10. Proyecciones Financieras'!B24 -> 11 | C28: ='10. Proyecciones Financieras'!C24 -> 3 | D28: ='10. Proyecciones Financieras'!D24 -> 20 | E28: ='10. Proyecciones Financieras'!E24 -> 131250 | F28: ='10. Proyecciones Financieras'!F24 -> 94500 | G28: ='10. Proyecciones Financieras'!G24 -> 225750 | H28: ='10. Proyecciones Financieras'!H24 -> 94500
A29: ='10. Proyecciones Financieras'!A25 -> Dic 2025 | B29: ='10. Proyecciones Financieras'!B25 -> 12 | C29: ='10. Proyecciones Financieras'!C25 -> 4 | D29: ='10. Proyecciones Financieras'!D25 -> 23 | E29: ='10. Proyecciones Financieras'!E25 -> 175000 | F29: ='10. Proyecciones Financieras'!F25 -> 110250 | G29: ='10. Proyecciones Financieras'!G25 -> 285250 | H29: ='10. Proyecciones Financieras'!H25 -> 110250
A30: ='10. Proyecciones Financieras'!A26 -> Ene 2026 | B30: ='10. Proyecciones Financieras'!B26 -> 13 | C30: ='10. Proyecciones Financieras'!C26 -> 4 | D30: ='10. Proyecciones Financieras'!D26 -> 26 | E30: ='10. Proyecciones Financieras'!E26 -> 175000 | F30: ='10. Proyecciones Financieras'!F26 -> 126000 | G30: ='10. Proyecciones Financieras'!G26 -> 301000 | H30: ='10. Proyecciones Financieras'!H26 -> 126000
A31: ='10. Proyecciones Financieras'!A27 -> 46054 | B31: ='10. Proyecciones Financieras'!B27 -> 14 | C31: ='10. Proyecciones Financieras'!C27 -> 4 | D31: ='10. Proyecciones Financieras'!D27 -> 29 | E31: ='10. Proyecciones Financieras'!E27 -> 175000 | F31: ='10. Proyecciones Financieras'!F27 -> 133875 | G31: ='10. Proyecciones Financieras'!G27 -> 308875 | H31: ='10. Proyecciones Financieras'!H27 -> 133875
A32: ='10. Proyecciones Financieras'!A28 -> 46082 | B32: ='10. Proyecciones Financieras'!B28 -> 15 | C32: ='10. Proyecciones Financieras'!C28 -> 5 | D32: ='10. Proyecciones Financieras'!D28 -> 33 | E32: ='10. Proyecciones Financieras'!E28 -> 218750 | F32: ='10. Proyecciones Financieras'!F28 -> 157500 | G32: ='10. Proyecciones Financieras'!G28 -> 376250 | H32: ='10. Proyecciones Financieras'!H28 -> 157500
A33: ='10. Proyecciones Financieras'!A29 -> Abr 2026 | B33: ='10. Proyecciones Financieras'!B29 -> 16 | C33: ='10. Proyecciones Financieras'!C29 -> 5 | D33: ='10. Proyecciones Financieras'!D29 -> 37 | E33: ='10. Proyecciones Financieras'!E29 -> 218750 | F33: ='10. Proyecciones Financieras'!F29 -> 173250 | G33: ='10. Proyecciones Financieras'!G29 -> 392000 | H33: ='10. Proyecciones Financieras'!H29 -> 173250
A34: ='10. Proyecciones Financieras'!A30 -> 46143 | B34: ='10. Proyecciones Financieras'!B30 -> 17 | C34: ='10. Proyecciones Financieras'!C30 -> 5 | D34: ='10. Proyecciones Financieras'!D30 -> 41 | E34: ='10. Proyecciones Financieras'!E30 -> 218750 | F34: ='10. Proyecciones Financieras'!F30 -> 196875 | G34: ='10. Proyecciones Financieras'!G30 -> 415625 | H34: ='10. Proyecciones Financieras'!H30 -> 196875
A35: ='10. Proyecciones Financieras'!A31 -> 46174 | B35: ='10. Proyecciones Financieras'!B31 -> 18 | C35: ='10. Proyecciones Financieras'!C31 -> 6 | D35: ='10. Proyecciones Financieras'!D31 -> 45 | E35: ='10. Proyecciones Financieras'!E31 -> 262500 | F35: ='10. Proyecciones Financieras'!F31 -> 212625 | G35: ='10. Proyecciones Financieras'!G31 -> 475125 | H35: ='10. Proyecciones Financieras'!H31 -> 212625
A36: ='10. Proyecciones Financieras'!A32 -> 46204 | B36: ='10. Proyecciones Financieras'!B32 -> 19 | C36: ='10. Proyecciones Financieras'!C32 -> 6 | D36: ='10. Proyecciones Financieras'!D32 -> 49 | E36: ='10. Proyecciones Financieras'!E32 -> 262500 | F36: ='10. Proyecciones Financieras'!F32 -> 228375 | G36: ='10. Proyecciones Financieras'!G32 -> 490875 | H36: ='10. Proyecciones Financieras'!H32 -> 228375
A37: ='10. Proyecciones Financieras'!A33 -> Ago 2026 | B37: ='10. Proyecciones Financieras'!B33 -> 20 | C37: ='10. Proyecciones Financieras'!C33 -> 6 | D37: ='10. Proyecciones Financieras'!D33 -> 53 | E37: ='10. Proyecciones Financieras'!E33 -> 262500 | F37: ='10. Proyecciones Financieras'!F33 -> 252000 | G37: ='10. Proyecciones Financieras'!G33 -> 514500 | H37: ='10. Proyecciones Financieras'!H33 -> 252000
... A41: ='10. Proyecciones Financieras'!A37 -> Dic 2026 | B41: ='10. Proyecciones Financieras'!B37 -> 24 | C41: ='10. Proyecciones Financieras'!C37 -> 8 | D41: ='10. Proyecciones Financieras'!D37 -> 73 | E41: ='10. Proyecciones Financieras'!E37 -> 350000 | F41: ='10. Proyecciones Financieras'!F37 -> 346500 | G41: ='10. Proyecciones Financieras'!G37 -> 696500 | H41: ='10. Proyecciones Financieras'!H37 -> 346500
A62: PUNTO DE EQUILIBRIO Y MÉTRICAS CLAVE
A63: Indicador | B63: Valor | D63: Indicador | E63: Valor | G63: Indicador | H63: Valor
...

Sheet 1. Resumen Ejecutivo
A1: PLAN DE NEGOCIOS — AGENCIA DE INTELIGENCIA ARTIFICIAL
A3: 1. RESUMEN EJECUTIVO
A5: CONCEPTO | B5: DETALLE
A6: Nombre | B6: Ryventis Solutions
A7: Tipo de empresa | B7: Agencia de Inteligencia Artificial (Servicios + Productos)
A8: Ubicación inicial | B8: México (operación 100% remota)
A9: Fundadores | B9: 2 personas — equipo técnico-comercial
A10: Fecha de inicio estimada | B10: 2025 (Fase de Validación)
A11: Inversión inicial requerida | B11: $0 USD (Bootstrapped)
A12: Modelo de ingresos | B12: Proyectos one-time + Suscripciones mensuales recurrentes
A13: Ticket promedio cliente | B13: $35,000 — $87,500 MXN por proyecto / mes
A14: Meta de ingresos (12 meses) | B14: $175,000 MXN/mes en ingresos recurrentes
A15: Clientes objetivo | B15: PYMES en sectores salud e inmobiliario (México)
A16: Servicios clave | B16: Chatbots, Automatización IA, Agentes Autónomos, Análisis de Datos
A18: VISIÓN A 5 AÑOS
A19: Año 1 | B19: Validar oferta, cerrar 3-5 clientes, $52,500-$87,500 MXN/mes
A20: Año 2 | B20: Escalar a $262,500-$350,000 MXN/mes, equipo 4-5 personas
A21: Año 3 | B21: Lanzar primer producto SaaS, $525,000+ MXN/mes
A22: Año 4 | B22: Consolidar 2 nichos (salud + inmobiliario), $875,000+ MXN/mes
A23: Año 5 | B23: Consultora especializada + productos propios, >$1,400,000 MXN/mes
A25: PROPUESTA DE VALOR
B26: Ayudamos a PYMES en México a implementar IA de forma práctica,
B27: rápida y accesible — sin necesidad de equipo técnico interno.
A29: DIFERENCIADORES CLAVE
A30: 1 | B30: Especialización en salud e inmobiliario (alto valor)
A31: 2 | B31: Implementación rápida: resultados en 2-4 semanas
A32: 3 | B32: Precio accesible vs. grandes consultoras
A33: 4 | B33: Modelo híbrido: servicio + suscripción recurrente
A34: 5 | B34: Fundadores con conocimiento profundo de IA aplicada

Sheet 2. Análisis de Mercado
A1: 2. ANÁLISIS DE MERCADO
A3: TAMAÑO DE MERCADO — IA EN MÉXICO
A4: Indicador | B4: Valor / Dato | C4: Fuente Ref.
A5: Mercado IA en México (2024) | B5: ~$1,200 millones USD | C5: IDC / Statista
A6: Crecimiento anual proyectado (CAGR) | B6: 28-35% anual hasta 2030 | C6: McKinsey LatAm
A7: Mercado IA en México (2028 estimado) | B7: >$4,000 millones USD | C7: Proyección propia
A8: PYMES en México | B8: >4.1 millones de empresas | C8: INEGI 2023
A9: % PYMES con baja adopción digital | B9: ~72% | C9: INEGI / CIDE
A10: Penetración actual de IA en PYMES MX | B10: <5% | C10: Estimado sector
A11: Gasto promedio PYME en tecnología/año | B11: $5,000 - $30,000 USD | C11: Referencia mercado
A13: OPORTUNIDAD EN PYMES
A14: Factor | B14: Descripción
A15: Mercado desatendido | B15: Las grandes consultoras ignoran a PYMES por ticket bajo
A16: Urgencia digital | B16: Post-COVID aceleró presión para digitalizar procesos
A17: Presupuesto accesible | B17: PYMES pueden invertir $1K-$5K USD/mes si ven ROI claro
A18: Decisión rápida | B18: Dueños de PYMES deciden solos — ciclo de venta más corto
A19: Crecimiento de competidores | B19: IA democratiza servicios antes exclusivos de grandes empresas
A21: TENDENCIAS IA — SECTOR SALUD (MÉXICO)
A22: Tendencia | B22: Aplicación / Oportunidad
A23: Chatbots médicos | B23: Triaje inicial, recordatorios de citas, atención 24/7
A24: Automatización administrativa | B24: Facturación, expedientes, agendamiento inteligente
A25: Análisis de datos clínicos | B25: Detección de patrones, reportes de desempeño
A26: Agentes autónomos | B26: Seguimiento de pacientes, alertas, gestión de inventario médico
A27: Valor percibido
A29: TENDENCIAS IA — SECTOR INMOBILIARIO (MÉXICO)
A30: Tendencia | B30: Aplicación / Oportunidad
A31: Chatbots de ventas | B31: Calificación de leads, atención 24/7, tours virtuales
A32: CRM con IA | B32: Seguimiento automático, scoring de prospectos
A33: Análisis de mercado | B33: Valuaciones automáticas, comparativos de zona
A34: Automatización de marketing
A35: Valor percibido | B35: Alto — cada lead perdido = miles de dólares en comisiones
A37: ANÁLISIS COMPETITIVO
A38: Competidor tipo | B38: Fortaleza | C38: Debilidad | D38: Nuestra oportunidad
A39: Grandes consultoras (Accenture, etc.) | B39: Marca, recursos | C39: Precio alto, no atienden PYMES | D39: Nicho desatendido
A40: Freelancers de IA | B40: Precio bajo | C40: Sin soporte, sin escalabilidad | D40: Servicio + continuidad
A41: Agencias digitales genéricas | B41: Red de contactos | C41: No especializadas en IA | D41: Especialización real
A42: Startups IA internacionales | B42: Tecnología avanzada | C42: Sin presencia local, idioma | D42: Proximidad + idioma

Sheet 3. Propuesta de Valor
A1: 3. PROPUESTA DE VALOR Y DIFERENCIACIÓN
A3: PROPUESTA DE VALOR CENTRAL
A4: Para: | B4: PYMES en México (salud e inmobiliario)
A5: Que necesitan: | B5: Implementar IA sin equipo técnico interno y con presupuesto limitado
A6: Ofrecemos: | B6: Soluciones de IA llave en mano: chatbots, automatización y agentes autónomos
A7: A diferencia de: | B7: Grandes consultoras (precio prohibitivo) o freelancers (sin soporte)
A8: Nuestra diferencia: | B8: Especialización en PYMES + resultados medibles en 30 días + soporte continuo
A10: VENTAJA COMPETITIVA RECOMENDADA
A11: Pilar | B11: Descripción | C11: Por qué funciona
A12: 1. Nicho profundo | B12: Especializarse en salud + inmobiliario (no generalistas) | C12: Menos competencia, ticket más alto, referencias sectoriales
A13: 2. Velocidad de entrega | B13: Garantizar primeros resultados en 2-4 semanas | C13: PYMES no tienen paciencia para proyectos de 6 meses
A14: 3. ROI demostrable | B14: Cuantificar el impacto: leads, tiempo ahorrado, costo reducido | C14: El dueño de PYME compra resultados, no tecnología
A15: 4. Modelo suscripción | B15: Convertir clientes en socios con retainer mensual desde $500 USD | C15: Ingresos predecibles + relación de largo plazo
A16: 5. Cercanía local | B16: Español, husos horarios MX, conocimiento del mercado local | C16: Ventaja vs. agencias extranjeras
A17: 6. Stack IA de vanguardia | B17: Usar GPT-4, Claude, Make/Zapier, agentes autónomos reales | C17: Credibilidad tecnológica diferenciadora
A19: POSICIONAMIENTO ESTRATÉGICO
A20: Posición actual (Año 1) | B20: Agencia generalista con foco inicial en salud e inmobiliario
A21: Posición Año 2-3 | B21: Consultora especializada en IA para PYMES salud + inmobiliario
A22: Posición Año 4-5 | B22: Empresa de IA con servicios + productos SaaS propios para el sector
A24: MENSAJE DE MARKETING CLAVE
A25: Tagline sugerido: | B25: IA que trabaja para tu negocio — sin complicaciones, con resultados.
A26: Pain point central: | B26: Los dueños de PYME pierden tiempo y dinero en tareas que la IA puede hacer mejor
A27: Promesa de venta: | B27: En 30 días implementamos tu primer agente de IA. Si no ves resultados, no cobras.
A29: BUYER PERSONAS
A30: Persona | B30: Perfil | C30: Pain point principal | D30: Solución que compramos
A31: Director clínica / hospital pequeño | B31: 45-60 años, dueño, no técnico | C31: Personal saturado, pacientes sin atención rápida | D31: Chatbot médico + automatización citas
A32: Agencia inmobiliaria mediana | B32: 35-50 años, enfocado en ventas | C32: Leads que no se atienden a tiempo, agentes ocupados | D32: Chatbot de calificación + CRM automatizado
A33: Consultorio dental o médico | B33: 30-45 años, dueño-operador | C33: Cancelaciones, recordatorios manuales, sin seguimiento | D33: Bot de WhatsApp + automatización recordatorios
A34: Desarrolladora inmobiliaria | B34: 40-55 años, gerente comercial | C34: Proceso de ventas lento, muchos prospectos sin seguir | D34: Agente autónomo de seguimiento + análisis

Sheet 4. Portafolio de Servicios
A1: 4. PORTAFOLIO DE SERVICIOS
A3: SERVICIOS INICIALES (AÑO 1)
A4: Servicio | B4: Descripción | C4: Entregable | D4: Precio (USD) | E4: Recurrencia
A5: Chatbot Inteligente (WhatsApp/Web) | B5: Bot con IA para atención, ventas o soporte 24/7 | C5: Bot funcional + flujos configurados | D5: $26,250 - $52,500 MXN | E5: Setup + $5,250-$8,750/mes
A6: Automatización de Procesos con IA | B6: Automatizar flujos: citas, facturación, seguimiento, reportes | C6: Flujos en Make/Zapier + documentación | D6: $17,500 - $43,750 MXN | E6: Setup + $3,500-$7,000/mes
A7: Agente Autónomo de Ventas/Soporte | B7: Agente que califica leads, hace seguimiento, responde y escala | C7: Agente configurado en plataforma IA | D7: $35,000 - $70,000 MXN | E7: Setup + $7,000-$14,000/mes
A8: Análisis de Datos con IA | B8: Dashboard + insights automáticos de datos del negocio | C8: Reporte + tablero interactivo | D8: $26,250 - $61,250 MXN | E8: Setup + $5,250-$10,500/mes
A9: Consultoría en Adopción de IA | B9: Diagnóstico + hoja de ruta de IA para el negocio | C9: Reporte estratégico + sesión ejecutiva | D9: $8,750 - $26,250 MXN | E9: One-time (puede evolucionar)
A10: Pack Starter IA | B10: Chatbot + 1 automatización + 1 mes soporte | C10: Paquete completo llave en mano | D10: $43,750 MXN | E10: Setup + $7,000/mes
A12: SERVICIOS ESPECIALIZADOS (AÑO 2-3)
A13: Servicio | B13: Sector | C13: Descripción | D13: Precio Est. (USD)
A14: Sistema de IA para Clínicas | B14: Salud | C14: Chatbot + agenda + expediente + recordatorios integrados | D14: $70,000 - $140,000 MXN
A15: Pipeline de Ventas IA Inmobiliario | B15: Inmobiliario | C15: CRM automatizado + agente de calificación + seguimiento | D15: $61,250 - $122,500 MXN
A16: Asistente IA para Agentes de Ventas | B16: Inmobiliario | C16: Copiloto IA para respuestas, propuestas y análisis de clientes | D16: $43,750 - $87,500 MXN
A17: Análisis Predictivo Médico | B17: Salud | C17: Modelos de predicción de demanda, ausentismo, inventario | D17: $52,500 - $105,000 MXN
A18: Capacitación Corporativa en IA | B18: Transversal | C18: Talleres prácticos de uso de IA para equipos de trabajo | D18: $14,000 - $35,000 MXN | E18: Por sesión
A20: PRODUCTOS ESCALABLES (AÑO 3-5)
A21: Producto | B21: Descripción | C21: Modelo de ingresos | D21: $2,625-$7,000/mes
A22: SaaS Chatbot para Clínicas | B22: Plataforma whitelabel de chatbot para salud (turnos, FAQs, triaje) | C22: Suscripción mensual | D22: $3,500-$8,750/mes
A23: SaaS Agente Inmobiliario IA | B23: Agente autónomo para agencias: califica, agenda y da seguimiento | C23: Suscripción mensual | D23: $1,697 - $5,197 MXN
A24: Plantillas IA Verticalizadas | B24: Flujos preconfigurados para salud e inmobiliario (Make/Zapier) | C24: Venta única | D24: $3,447 - $8,697 MXN
A25: Curso IA para PYMES MX | B25: Curso online práctico de implementación de IA en negocios | C25: Venta única + membresía | D25: Por uso / $1,732+/mes
A26: API / Microservicio IA propio | B26: Módulo IA especializado (análisis docs, scoring, resúmenes) | C26: API usage / suscripción | D26: Por uso / $99+/mes
A28: MODELO DE PRECIOS SUGERIDO (RESUMEN)
A29: Tier | B29: Nombre | C29: Qué incluye | D29: $5,232 - $8,732/mes | E29: Público objetivo
A30: Básico | B30: Starter AI | C30: 1 chatbot + soporte básico | D30: $12,232 - $17,482/mes | E30: PYME pequeña (<10 empleados)
A31: Medio | B31: Pro AI | C31: Chatbot + 2 automatizaciones + dashboard | D31: $26,250 - $52,500/mes | E31: PYME mediana (10-50 empleados)
A32: Premium | B32: Enterprise AI | C32: Suite completa + agente autónomo + análisis | D32: $35,000 - $140,000 MXN | E32: Empresa mediana (50+ empleados)
A33: Proyecto | B33: One-time | C33: Implementación personalizada sin retainer | D33: $2,000 - $8,000 | E33: Clientes que prefieren pago único

Sheet 5. Modelo de Ingresos
A1: 5. MODELO DE INGRESOS
A3: ESTRUCTURA DE INGRESOS
A4: Tipo de ingreso | B4: Descripción | C4: Cuándo aplica | D4: Ticket promedio | E4: Frecuencia
A5: Proyecto one-time | B5: Implementación inicial, setup, configuración | C5: Cierre de contrato | D5: $26,250 - $87,500 MXN | E5: Una vez
A6: Retainer mensual | B6: Soporte, mantenimiento, mejoras continuas | C6: Mes 2 en adelante | D6: $3,500 - $14,000 MXN/mes | E6: Mensual recurrente
A7: Suscripción SaaS (futuro) | B7: Licencia de producto propio | C7: Año 3+ | D7: $1,732 - $8,750 MXN/mes | E7: Mensual recurrente
A8: Capacitación / Talleres | B8: Cursos, workshops para equipos | C8: Ocasional | D8: $8,750 - $35,000 MXN | E8: Esporádico
A9: Consultoría estratégica | B9: Sesiones de estrategia IA a nivel directivo | C9: Proyectos maduros | D9: $17,500 - $52,500 MXN | E9: Por proyecto
A11: ESCENARIOS DE INGRESOS MENSUALES (AÑO 1)
A12: Escenario | B12: Clientes activos | C12: Ingreso proyectos | D12: Ingreso recurrente | E12: Total mensual | F12: Meta alcanzada
A13: Pesimista | B13: 1 | C13: 35000 | D13: 5250 | E13: 40250 | F13: No
A14: Base (realista) | B14: 3 | C14: 78750 | D14: 21000 | E14: 99750 | F14: Parcial
A15: Optimista | B15: 5 | C15: 140000 | D15: 43750 | E15: 183750 | F15: Sí ✓
A17: ESCENARIOS DE INGRESOS MENSUALES (AÑO 2)
A18: Escenario | B18: Clientes activos | C18: Ingreso proyectos | D18: Ingreso recurrente | E18: Total mensual
A19: Pesimista | B19: 5 | C19: 87500 | D19: 52500 | E19: 140000
A20: Base (realista) | B20: 10 | C20: 175000 | D20: 105000 | E20: 280000
A21: Optimista | B21: 18 | C21: 315000 | D21: 210000 | E21: 525000
A23: ESTRATEGIA DE SUSCRIPCIÓN MENSUAL
A24: Elemento | B24: Detalle
A25: Primer mes gratis o descuento | B25: Para los primeros 5 clientes — genera confianza y testimoniales
A26: Contrato mínimo 3 meses | B26: Asegura estabilidad de flujo y tiempo de resultados
A27: Escalabilidad del plan | B27: El cliente sube de plan conforme crece — ingresos aumentan sin nuevo cliente
A28: Penalización por cancelación | B28: Pago anual con 2 meses de descuento — mejora flujo de caja
A29: Incentivo anual | B29: Pago anual con 2 meses de descuento — mejora flujo de caja
A31: MÉTRICAS CLAVE A MONITOREAR
A32: Métrica | B32: Fórmula / Descripción | C32: Meta Año 1
A33: MRR (Ingresos Recurrentes Mensuales) | B33: Suma de retainers activos | C33: $87,500+ MXN
A34: ARR (Ingresos Anuales Recurrentes) | B34: MRR × 12 | C34: $1,050,000+ MXN
A35: CAC (Costo Adquisición Cliente) | B35: Gasto marketing / clientes nuevos | C35: <$3,500 MXN
A36: LTV (Valor de vida del cliente) | B36: Ticket promedio × meses promedio relación | C36: >$87,500 MXN
A37: Ratio LTV/CAC | B37: LTV / CAC | C37: >15x
A38: Churn mensual | B38: % clientes que cancelan por mes | C38: <5%
A39: Ticket promedio por cliente | B39: Ingreso total / número de clientes | C39: $14,000+ MXN/mes

Sheet 6. Adquisición de Clientes
A1: 6. ESTRATEGIA DE ADQUISICIÓN DE CLIENTES
A3: CANALES DE ADQUISICIÓN (BOOTSTRAPPED — $0)
A4: Canal | B4: Táctica específica | C4: Costo | D4: Tiempo a resultados | E4: Prioridad
A5: LinkedIn Outbound | B5: Mensajes directos a dueños de clínicas y agencias inmobiliarias | C5: 0 | D5: 2-4 semanas | E5: 🔴 Alta
A6: Contenido educativo (LinkedIn/IG) | B6: Posts sobre casos de uso IA para PYMES — atraer leads inbound | C6: 0 | D6: 2-3 meses | E6: 🔴 Alta
A7: Referidos y boca a boca | B7: Pedir referidos activamente a cada cliente; ofrecer descuento por referir | C7: 0 | D7: Inmediato si hay clientes | E7: 🔴 Alta
A8: Grupos de WhatsApp / Facebook PYMES | B8: Participar en grupos sectoriales, compartir valor, no vender directo | C8: 0 | D8: 4-6 semanas | E8: 🟡 Media
A9: Alianzas con contadores / consultores | B9: Alianza con asesores que ya tienen PYMES como clientes | C9: $5,250-$8,750/mes | D9: 4-8 semanas | E9: 🟡 Media
A10: Cold email personalizado | B10: Emails ultra-personalizados a clínicas y agencias (50/semana) | C10: 0 | D10: 3-6 semanas | E10: 🟡 Media
A11: YouTube / Podcast
A12: Google Ads (futuro) | B12: Cuando haya presupuesto: keywords nicho muy específicos | C12: $300-500/mes | D12: 2-4 semanas | E12: 🟢 Futuro
A14: FUNNEL DE VENTAS RECOMENDADO
A15: Etapa | B15: Acción | C15: Herramienta | D15: Meta de conversión
A16: 1. Atención | B16: Post/video educativo sobre IA en su sector | C16: LinkedIn / IG / YouTube | D16: 100-500 vistos/semana
A17: 2. Interés | B17: Lead magnet: guía gratuita 'Cómo usar IA en tu negocio' | C17: Google Forms / Notion | D17: 10% de alcance se registra
A18: 3. Consideración | B18: Demo gratuita de 30 min + propuesta personalizada | C18: Zoom + Notion/Canva | D18: 50% de demos = propuesta enviada
A19: 4. Decisión | B19: Propuesta de valor + caso de estudio + garantía 30 días | C19: PDF / Loom video | D19: 30-40% de propuestas = cierre
A20: 5. Retención | B20: Check-in mensual + reporte de resultados + upsell | C20: Notion + WhatsApp + Loom | D20: Churn <5% mensual
A21: 6. Referido
A23: SECUENCIA DE OUTBOUND LINKEDIN (SEMANA 1-4)
A24: Semana | B24: Acción diaria | C24: Volumen | D24: Objetivo
A25: Semana 1 | B25: Conectar con 20 dueños de clínicas o agencias en LinkedIn | C25: 20 conexiones/día | D25: Construir red inicial de 500+
A26: Semana 2 | B26: Enviar mensaje de valor (sin venta): compartir insight IA útil | C26: 10 mensajes/día | D26: Establecer conversaciones
A27: Semana 3 | B27: Invitar a demo gratuita: 'Te muestro cómo IA puede [resultado específico]' | C27: 5 invitaciones/día | D27: 3-5 demos agendadas
A28: Semana 4
A30: PROPUESTA DE VENTA RÁPIDA (ESTRATEGIA 'PIE EN LA PUERTA') | B30: Diagnóstico rápido: '3 cosas que IA puede mejorar en tu negocio HOY'
A31: Paso | B31: Pequeño proyecto de 1-2 semanas: chatbot básico o automatización simple — $8,750-$14,000 MXN
A32: 1. Audit gratuito (30 min) | B32: Con el quick win funcionando, proponer el proyecto completo $35,000-$87,500 MXN
A33: 2. Quick win ($500-$800) | B33: Después del proyecto, ofrecer mantenimiento + mejoras por $5,250-$10,500/mes
A34: 3. Propuesta expandida | B34: Con el quick win funcionando, proponer el proyecto completo $2K-$5K
A35: 4. Suscripción mensual | B35: Después del proyecto, ofrecer mantenimiento + mejoras por $300-$600/mes

Sheet 7. Roadmap 0-5 Años
A1: 7. ROADMAP DE CRECIMIENTO — 0 A 5 AÑOS
A3: ETAPA 1: VALIDACIÓN (Meses 1-6)
A4: Área | B4: Acciones clave | C4: KPI / Meta
A5: Oferta | B5: Definir 2-3 servicios concretos (chatbot + automatización + consultoría) | C5: $35,000-$52,500 MXN al mes 6
A6: Mercado | B6: Elegir 1 nicho inicial (recomendado: inmobiliario por ciclo de venta más corto) | C6: $140,000-$210,000 MXN/mes
A7: Primeros clientes | B7: Cerrar 1-3 clientes piloto (con descuento o incluso gratuito para testimoniales) | C7: $525,000+ MXN/mes
A8: Producto mínimo | B8: Crear demo funcional de chatbot para mostrar en ventas | C8: $875,000+ MXN/mes
A9: Ingresos | B9: Llegar a $2,000 - $3,000 USD/mes de ingresos recurrentes | C9: >$1,400,000 MXN/mes
A10: Procesos | B10: Crear templates, flujos y SOP para entregar servicios con rapidez | C10: 3-5 SOPs documentados
A11: Tecnología | B11: Setup stack: ChatGPT API + Make + Notion + CRM simple | C11: Stack operativo en semana 1
A13: ETAPA 2: TRACCIÓN (Meses 7-18)
A14: Área | B14: Acciones clave | C14: KPI / Meta
A15: Clientes | B15: Escalar a 8-12 clientes activos. Foco en retainers mensuales | C15: $8K-$12K MRR
A16: Equipo | B16: Contratar 1er colaborador (dev IA freelance o PM part-time) | C16: Primer hire al mes 10-12
A17: Nicho | B17: Profundizar en salud + inmobiliario. Crear paquetes sectoriales | C17: 2 paquetes verticales listos
A18: Marketing | B18: Crear contenido educativo consistente en LinkedIn (3x/semana) | C18: 500+ seguidores relevantes
A19: Procesos | B19: Automatizar onboarding de clientes, reportes y seguimiento | C19: Onboarding <48 horas
A20: Alianzas | B20: Cerrar 2-3 alianzas con contadores, consultores o agencias digitales | C20: 5+ referidos por alianzas
A21: Producto
A23: ETAPA 3: ESCALAMIENTO (Meses 19-36)
A24: Área | B24: Acciones clave | C24: $437,500+ MRR
A25: Ingresos | B25: Meta: $20K-$35K USD/mes. Mezcla servicios + productos | C25: $25K MRR
A26: Equipo | B26: Equipo de 4-6 personas: 2 devs IA, 1 comercial, 1 PM, 1 diseñador | C26: Equipo consolidado
A27: SaaS | B27: Lanzar versión beta de primer producto SaaS (chatbot clínicas o inmobiliario) | C27: 50 usuarios beta
A28: Marketing | B28: Invertir en contenido + $500-1,000/mes en ads segmentados | C28: 50+ leads/mes inbound
A29: Expansión
A30: Casos de éxito | B30: Publicar 5-10 casos de éxito documentados con resultados reales | C30: $1,050,000+ MRR
A32: ETAPA 4: CONSOLIDACIÓN (Años 4-5)
A33: Área | B33: Acciones clave | C33: KPI / Meta
A34: Ingresos | B34: Meta: $50K-$80K+ USD/mes. 30%+ de ingresos pasivos | C34: $60K+ MRR
A35: Productos | B35: SaaS propio con 200+ usuarios pagos en 2 verticales | C35: 200+ suscriptores SaaS
A36: Equipo | B36: 8-15 personas. Estructura: ventas / delivery / producto / ops | C36: Organización formal
A37: Marca | B37: Posicionarse como referencia en IA para PYMES en México | C37: Media mentions + eventos
A38: Inversión | B38: Considerar ronda pre-seed o ángel si el SaaS despega | C38: $250K-$1M si aplica
A39: Expansión LatAm | B39: Colombia, Chile o Argentina como siguiente mercado | C39: 1 mercado nuevo año 5

Sheet 8. Plan Operativo
A1: 8. PLAN OPERATIVO — 2 PERSONAS, RECURSOS LIMITADOS
A3: DIVISIÓN DE ROLES (2 FUNDADORES)
A4: Rol | B4: Responsabilidades principales | C4: Horas semanales (inicial)
A5: Fundador A — Técnico / Delivery | B5: Implementar chatbots, automatizaciones, agentes IA. Delivery de proyectos. | C5: 3 hrs/semana (escalar a 10+)
A6: Fundador B — Comercial / Estrategia | B6: Prospección, demos, cierre ventas, propuestas, gestión clientes. | C6: 3 hrs/semana (escalar a 10+)
A7: Ambos | B7: Estrategia, roadmap, finanzas, decisiones clave, contenido (cuando aplique) | C7: 1 hr/semana reunión
A9: RUTINA SEMANAL RECOMENDADA (FASE INICIAL)
A10: Día | B10: Fundador A (Técnico) | C10: Fundador B (Comercial)
A11: Lunes | B11: Revisar proyectos activos, avances | C11: Enviar 20 conexiones LinkedIn, 10 mensajes
A12: Martes | B12: Trabajo técnico: chatbot/automatización | C12: Agendar demos, responder prospectos
A13: Miércoles | B13: Trabajo técnico + documentación SOP | C13: Realizar demos, enviar propuestas
A14: Jueves | B14: Testing, ajustes, entrega de avances | C14: Follow-up clientes, gestión contratos
A15: Viernes (30 min) | B15: Reunión semanal: revisión KPIs, ajustes | C15: Reunión semanal: revisión KPIs, ajustes
A17: PRIORIZACIÓN DE TAREAS (FRAMEWORK EISENHOWER IA)
A18: Cuadrante | B18: Tipo de tarea | C18: Ejemplos
A19: 🔴 Urgente + Importante | B19: Hacer AHORA | C19: Entregar proyecto cliente, responder prospecto caliente
A20: 🟡 Importante, no urgente | B20: Planificar y ejecutar | C20: Crear templates, contenido, mejorar procesos
A21: 🟢 Urgente, no importante | B21: Delegar o automatizar | C21: Reportes, recordatorios, emails de seguimiento
A22: ⚪ Ni urgente ni importante | B22: Eliminar | C22: Reuniones innecesarias, tareas administrativas repetitivas
A24: AUTOMATIZACIÓN INTERNA (PROCESOS PROPIOS)
A25: Proceso a automatizar | B25: Herramienta | C25: Tiempo ahorrado/semana
A26: Onboarding de clientes | B26: Notion + formulario Google + Make | C26: 2-3 horas
A27: Reportes mensuales de resultados | B27: Make + Google Sheets + plantilla Notion | C27: 2-4 horas
A28: Seguimiento de prospectos | B28: CRM simple (HubSpot free) + recordatorios | C28: 1-2 horas
A29: Facturación y cobros | B29: Stripe + Notion + email automático | C29: 1 hora
A30: Gestión de redes sociales | B30: Buffer / Metricool (programar contenido) | C30: 1-2 horas
A31: Atención clientes (FAQs)
A33: HERRAMIENTAS DE GESTIÓN INTERNA
A34: Área | B34: Herramienta | C34: Plan
A35: Gestión de proyectos | B35: Notion | C35: Gratuito
A36: Comunicación interna | B36: WhatsApp + Slack (futuro) | C36: Gratuito
A37: CRM / Prospectos | B37: HubSpot CRM | C37: Gratuito
A38: Videollamadas y demos | B38: Zoom / Google Meet | C38: Gratuito
A39: Contratos y propuestas | B39: PandaDoc (free) / Notion | C39: Gratuito
A40: Pagos internacionales | B40: Stripe / Wise | C40: % por transacción
A41: Almacenamiento | B41: Google Drive | C41: Gratuito (15 GB)

Sheet 9. Stack Tecnológico
A1: 9. STACK TECNOLÓGICO RECOMENDADO
A3: STACK BASE — AÑO 1 (MÍNIMO VIABLE)
A4: Categoría | B4: Herramienta | C4: Uso principal | D4: Costo/mes | E4: Prioridad
A5: LLM / IA Principal | B5: Anthropic Claude API | C5: Motor de chatbots y agentes IA | D5: $350-$1,750/mes | E5: 🔴 Esencial
A6: LLM Alternativo | B6: Google Gemini API | C6: Razonamiento complejo, análisis | D6: $350-$1,400/mes | E6: 🔴 Esencial
A7: Automatización | B7: Make (Integromat) | C7: Flujos, integraciones, webhooks | D7: $157-$507/mes | E7: 🔴 Esencial
A8: Automatización alt. | B8: Zapier | C8: Integraciones rápidas no-code | D8: $332-$857/mes | E8: 🟡 Opcional
A9: Chatbot UI / Deploy | B9: Botpress / Voiceflow | C9: Construir y desplegar chatbots | D9: $0-$857/mes | E9: 🔴 Esencial
A10: Base de conocimiento | B10: Notion AI / Obsidian | C10: Documentación y gestión interna | D10: $0-$175/mes | E10: 🟡 Media
A11: Vector DB (RAG) | B11: Pinecone / Supabase pgvector | C11: Búsqueda semántica para agentes | D11: $0-$437/mes | E11: 🟡 Media
A12: Mensajería / WhatsApp | B12: Twilio / Meta Business API | C12: Canal de entrega de chatbots | D12: $175-$875/mes | E12: 🔴 Esencial
A13: Analítica / Datos
A14: Hosting / Deploy | B14: Vercel / Railway / Render | C14: Hosting de apps y APIs | D14: $0-$437/mes | E14: 🟡 Media
A16: STACK AVANZADO — AÑO 2-3 (ESCALA) | D16: $0 (código abierto)
A17: Categoría | B17: Herramienta | C17: Uso principal | D17: $0-$437/mes
A18: Agentes autónomos | B18: LangChain + LangGraph | C18: Construcción de agentes complejos | D18: $0-$350/mes
A19: Agentes no-code | B19: n8n (self-hosted) / Dify.ai | C19: Agentes visuales para clientes | D19: Variable
A20: Memoria de agentes | B20: Mem0 / Redis | C20: Contexto persistente en agentes | D20: $437/mes
A21: Fine-tuning | B21: OpenAI fine-tuning / Replicate | C21: Modelos personalizados por cliente | D21: $0-$437/mes
A22: Plataforma interna
A23: Analytics de uso | B23: PostHog / Mixpanel | C23: Medir comportamiento de usuarios | D23: $0-25 USD
A24: CRM avanzado | B24: HubSpot (pago) / Pipedrive | C24: Gestión avanzada de ventas | D24: $45-90 USD
A26: ARQUITECTURA BASE RECOMENDADA
A27: Componente | B27: Descripción
A28: Capa de entrada | B28: WhatsApp / Web / Telegram → Twilio/Meta API recibe mensaje
A29: Capa de orquestación
A30: Capa de IA | B30: GPT-4o o Claude → procesa, razona, genera respuesta con RAG
A31: Capa de datos | B31: Supabase/Postgres → historial de conversaciones, leads, datos cliente
A32: Capa de integración | B32: APIs externas: CRM, calendario, ERP del cliente
A33: Capa de análisis | B33: Google Sheets + Looker Studio → reportes de desempeño para cliente
A35: EVOLUCIÓN DEL STACK A 5 AÑOS
A36: Año | B36: Adición al stack | C36: Objetivo
A37: Año 1 | B37: GPT-4o + Claude + Make + Botpress + Twilio | C37: Operar y entregar servicios
A38: Año 2 | B38: LangChain + n8n + Pinecone + Supabase | C38: Agentes más complejos y escalables
A39: Año 3 | B39: Dify.ai + fine-tuning + API propia + PostHog | C39: Productos propios y plataforma
A40: Año 4 | B40: SaaS propio (Next.js + Supabase + OpenAI) | C40: Producto escalable B2B
A41: Año 5 | B41: Stack vertical propio por industria | C41: Plataforma IA propietaria para PYMES

Sheet 10. Proyecciones Financieras
A1: 10. PROYECCIONES FINANCIERAS — 5 AÑOS (PESOS MEXICANOS) | J1: Año | K1: Total Ingresos (MXN) | L1: Costos (MXN) | M1: EBITDA (MXN)
J2: Año 1 | K2: 1013250 | L2: 88200 | M2: 925050
A3: SUPUESTOS BASE (AJUSTABLES) | J3: Año 2 | K3: 2793000 | L3: 540330 | M3: 2252670
A4: Parámetro | B4: Valor | J4: Año 3 | K4: 5607000 | L4: 1159830 | M4: 4447170
A5: Ticket proyecto promedio (MXN) | B5: 43750 | J5: Año 4 | K5: 9177000 | L5: 2216130 | M5: 6960870
A6: Retainer mensual promedio (MXN) | B6: 7875 | J6: Año 5 | K6: 13881000 | L6: 3792600 | M6: 10088400
A7: % clientes que toman retainer | B7: 0.6
A8: Nuevos clientes/mes (inicial) | B8: 1
A9: Churn mensual estimado | B9: 0.04
A10: Tipo de cambio referencia USD/MXN | B10: 17.5
A12: PROYECCIÓN MENSUAL — AÑO 1 y AÑO 2 (24 MESES)
A13: Mes | B13: Mes # | C13: Clientes nuevos | D13: Clientes activos | E13: Ing. Proyectos (MXN) | F13: Ing. Recurrente (MXN) | G13: Total Ingresos (MXN) | H13: MRR (MXN)
A14: Ene 2025 | B14: 1 | C14: 1 | D14: 1 | E14: 43750 | F14: 7875 | G14: 51625 | H14: 7875
A15: 45689 | B15: 2 | C15: 1 | D15: 2 | E15: 43750 | F15: 7875 | G15: 51625 | H15: 7875
A16: 45717 | B16: 3 | C16: 1 | D16: 3 | E16: 43750 | F16: 15750 | G16: 59500 | H16: 15750
A17: Abr 2025 | B17: 4 | C17: 2 | D17: 5 | E17: 87500 | F17: 23625 | G17: 111125 | H17: 23625
A18: 45778 | B18: 5 | C18: 2 | D18: 7 | E18: 87500 | F18: 31500 | G18: 119000 | H18: 31500
A19: 45809 | B19: 6 | C19: 2 | D19: 9 | E19: 87500 | F19: 39375 | G19: 126875 | H19: 39375
A20: 45839 | B20: 7 | C20: 2 | D20: 11 | E20: 87500 | F20: 55125 | G20: 142625 | H20: 55125
A21: Ago 2025 | B21: 8 | C21: 3 | D21: 14 | E21: 131250 | F21: 63000 | G21: 194250 | H21: 63000
A22: 45901 | B22: 9 | C22: 3 | D22: 16 | E22: 131250 | F22: 78750 | G22: 210000 | H22: 78750
A23: 45931 | B23: 10 | C23: 3 | D23: 18 | E23: 131250 | F23: 86625 | G23: 217875 | H23: 86625
A24: 45962 | B24: 11 | C24: 3 | D24: 20 | E24: 131250 | F24: 94500 | G24: 225750 | H24: 94500
A25: Dic 2025 | B25: 12 | C25: 4 | D25: 23 | E25: 175000 | F25: 110250 | G25: 285250 | H25: 110250
A26: Ene 2026 | B26: 13 | C26: 4 | D26: 26 | E26: 175000 | F26: 126000 | G26: 301000 | H26: 126000
A27: 46054 | B27: 14 | C27: 4 | D27: 29 | E27: 175000 | F27: 133875 | G27: 308875 | H27: 133875
A28: 46082 | B28: 15 | C28: 5 | D28: 33 | E28: 218750 | F28: 157500 | G28: 376250 | H28: 157500
A29: Abr 2026 | B29: 16 | C29: 5 | D29: 37 | E29: 218750 | F29: 173250 | G29: 392000 | H29: 173250
A30: 46143 | B30: 17 | C30: 5 | D30: 41 | E30: 218750 | F30: 196875 | G30: 415625 | H30: 196875
A31: 46174 | B31: 18 | C31: 6 | D31: 45 | E31: 262500 | F31: 212625 | G31: 475125 | H31: 212625
A32: 46204 | B32: 19 | C32: 6 | D32: 49 | E32: 262500 | F32: 228375 | G32: 490875 | H32: 228375
A33: Ago 2026 | B33: 20 | C33: 6 | D33: 53 | E33: 262500 | F33: 252000 | G33: 514500 | H33: 252000
A34: 46266 | B34: 21 | C34: 7 | D34: 58 | E34: 306250 | F34: 275625 | G34: 581875 | H34: 275625
A35: 46296 | B35: 22 | C35: 7 | D35: 63 | E35: 306250 | F35: 299250 | G35: 605500 | H35: 299250
A36: 46327 | B36: 23 | C36: 8 | D36: 68 | E36: 350000 | F36: 322875 | G36: 672875 | H36: 322875
A37: Dic 2026 | B37: 24 | C37: 8 | D37: 73 | E37: 350000 | F37: 346500 | G37: 696500 | H37: 346500
A39: COSTOS ESTIMADOS MENSUALES POR AÑO (MXN)
A40: Categoría de costo | B40: Descripción | C40: Año 1 (MXN) | D40: Año 2 (MXN) | E40: Año 3 (MXN) | F40: Año 4 (MXN) | G40: Año 5 (MXN)
A41: Herramientas IA (APIs) | B41: OpenAI + Claude + Twilio + Make | C41: 3500 | D41: 7000 | E41: 12250 | F41: 21000 | G41: 35000
A42: Herramientas operativas | B42: Notion + CRM + Hosting + Zoom | C42: 875 | D42: 1750 | E42: 3500 | F42: 6125 | G42: 8750
...

Sheet 11. Escalabilidad
A1: 11. ESTRATEGIA DE ESCALABILIDAD — DE SERVICIOS A PRODUCTOS
A3: RUTA DE EVOLUCIÓN DEL NEGOCIO
A4: Fase | B4: Modelo | C4: Característica principal | D4: Ingresos esperados
A5: Fase 1 (Mes 1-12) | B5: Agencia de servicios | C5: 100% tiempo por dinero. Proyectos y retainers | D5: $35,000-$140,000 MXN/mes
A6: Fase 2 (Mes 12-24) | B6: Agencia con productos embrión | C6: Servicios + primeras plantillas y mini-productos | D6: $175,000-$350,000 MXN/mes
A7: Fase 3 (Mes 24-36) | B7: Híbrido servicios + SaaS beta | C7: Lanzar SaaS vertical. Servicios financian desarrollo | D7: $350,000-$700,000 MXN/mes
A8: Fase 4 (Mes 36-48) | B8: Empresa de productos con servicios premium | C8: SaaS como motor principal. Servicios para clientes estratégicos | D8: $700,000-$1,225,000 MXN/mes
A9: Fase 5 (Mes 48-60) | B9: Plataforma IA propietaria | C9: Ingresos mayoritariamente pasivos/escalables | D9: $1,225,000-$1,750,000+ MXN/mes
A11: IDEAS DE PRODUCTOS SAAS — VERTICALES PRIORITARIOS
A12: Producto | B12: Descripción | C12: Mercado objetivo | D12: Precio estimado
A13: SaaS Chatbot para Clínicas | B13: Plataforma de chatbot + agendamiento + recordatorios para salud | C13: Clínicas, consultorios, hospitales pequeños MX | D13: $2,625-$7,000/mes
A14: SaaS Agente Inmobiliario IA | B14: Agente autónomo que califica, agenda y da seguimiento a leads | C14: Agencias inmobiliarias, desarrolladoras MX/LatAm | D14: $3,500-$8,750/mes
A15: SaaS Automatización PYME | B15: Suite de automatizaciones pre-configuradas para PYMES | C15: PYMES en general (horizontal) | D15: $1,732-$4,375/mes
A16: SaaS Análisis de Datos PYME | B16: Dashboards inteligentes conectados a datos del negocio | C16: PYMES con datos dispersos | D16: $2,625-$6,125/mes
A17: API de Documentos IA | B17: Procesamiento y extracción de datos de PDFs, contratos, facturas | C17: Despachos, inmobiliarias, hospitales | D17: Por volumen / $1,732+/mes
A19: ESTRATEGIA DE TRANSICIÓN SERVICIO → PRODUCTO
A20: Paso | B20: Acción | C20: Cuándo
A21: 1. Identificar patrón repetible | B21: Detectar qué solución se repite más entre clientes (mismo problema) | C21: Mes 3-6
A22: 2. Crear plantilla/template vendible | B22: Documentar y empaquetar la solución como producto reutilizable | C22: Mes 6-9
A23: 3. Validar con 3-5 clientes piloto | B23: Cobrar precio reducido a cambio de feedback y testimonio | C23: Mes 9-12
A24: 4. Construir MVP del SaaS | B24: Versión mínima funcional del producto. Sin sobre-ingeniería | C24: Mes 12-18
A25: 5. Lanzar beta privada | B25: 10-20 usuarios beta. Iterar rápido. | C25: Mes 18-24
A26: 6. Lanzar comercialmente
A28: GENERACIÓN DE INGRESOS PASIVOS / SEMI-PASIVOS | C28: $87,500-$875,000+ MXN/mes
A29: Tipo de ingreso | B29: Mecanismo | C29: $8,750-$52,500 MXN/mes
A30: SaaS recurrente | B30: Usuarios pagando suscripción mensual o anual | C30: $8,750-$87,500 MXN/mes
A31: Plantillas / Templates IA | B31: Venta de flujos pre-configurados en Gumroad / sitio propio | C31: $3,500-$17,500 MXN/mes
A32: Cursos online | B32: Curso de IA para PYMES en Hotmart / Teachable / Udemy | C32: $17,500-$175,000 MXN/mes
A33: Afiliados de herramientas | B33: Comisiones por recomendar Make, Botpress, Voiceflow, etc. | C33: $200-$1K USD/mes
A34: Licencias white-label | B34: Licenciar soluciones propias a otras agencias o partners | C34: $1K-$10K USD/mes

Sheet 12. Riesgos y Mitigación
A1: 12. RIESGOS Y MITIGACIÓN
A3: MATRIZ DE RIESGOS
A4: Riesgo | B4: Probabilidad | C4: Impacto | D4: Estrategia de mitigación | E4: Semáforo
A5: Pocos clientes en los primeros meses | B5: Alta | C5: Alto | D5: Outbound agresivo desde día 1. Ofrecer piloto gratuito a 1-2 clientes para generar casos de éxito | E5: 🔴
A6: Dependencia de APIs externas (OpenAI, etc.) | B6: Media | C6: Alto | D6: Usar múltiples proveedores (OpenAI + Claude + Groq). Tener fallback configurado | E6: 🟡
A7: Cambio de precios en APIs IA | B7: Media | C7: Medio | D7: Contratos con clientes incluyen cláusula de ajuste por costos de infraestructura | E7: 🟡
A8: Competidor directo en el nicho | B8: Alta | C8: Medio | D8: Especializarse profundamente en 1-2 sectores. Ventaja por conocimiento del dominio | E8: 🟡
A9: Cliente grande no paga a tiempo | B9: Media | C9: Alto | D9: Cobrar 50% adelantado ($17,500+ MXN). Usar Stripe. Contratos claros. | E9: 🟡
A10: Solo 2 personas = cuello de botella | B10: Alta | C10: Alto | D10: Automatizar delivery al máximo. Templates reutilizables. Contratar freelancer en mes 10 | E10: 🔴
A11: Falta de tiempo (3 hrs/semana por persona) | B11: Alta | C11: Alto | D11: Priorizar 1 canal de adquisición y 1-2 servicios. Crecer solo cuando haya resultados | E11: 🔴
A12: Tecnología obsoleta o reemplazada | B12: Baja | C12: Alto | D12: Actualización continua. Stack modular que permite swap de componentes | E12: 🟡
A13: Problemas legales o de privacidad de datos | B13: Baja | C13: Alto | D13: Contratos con cláusulas de privacidad. Cumplir con LFPDPPP (México). Asesor legal básico | E13: 🟡
A14: Dificultad para cobrar en USD siendo empresa MX | B14: Media | C14: Medio | D14: Usar Stripe, Wise o PayPal para cobros internacionales. Facturación en MXN si aplica | E14: 🟡
A15: El cliente no ve ROI y cancela | B15: Media | C15: Alto | D15: Definir KPIs de éxito. Reporte mensual. Check-in a los 30 días. | E15: 🔴
A16: Quemarse / fatiga de los fundadores
A18: PLAN DE CONTINGENCIA — ESCENARIO PESIMISTA (0 clientes en 3 meses) | B18: Pequeño proyecto piloto a $8,750 MXN (quick win demostrable)
A19: Paso | B19: Acción de contingencia
A20: 1 | B20: Hacer pivote de nicho: probar con una industria diferente (ej. restaurantes, e-commerce)
A21: 2 | B21: Bajar precio de entrada: ofrecer proyecto piloto a $500 USD (quick win demostrable)
A22: 3 | B22: Activar red personal: pedir a conocidos, familia, ex-colegas que recomienden o sean primeros clientes
A23: 4
A24: 5 | B24: Validar mensaje: hacer 20 entrevistas a dueños de PYME para entender su problema real
A26: INDICADORES DE ALERTA TEMPRANA
A27: MRR decreciente 2 meses consecutivos | B27: Umbral de alarma | C27: Acción inmediata
A28: MRR decreciente 2 meses consecutivos | B28: MRR < mes anterior | C28: Revisar oferta, precio y pipeline urgente
A29: 0 demos agendadas en 2 semanas | B29: 3+ clientes cancelan en 1 mes | C29: Auditar entrega, calidad y expectativas
A30: Costo API > 30% de ingresos | B30: Sin actividad comercial | C30: Revisar mensaje de venta y canal outbound
A31: Costo API > 30% de ingresos | B31: Margen comprimido | C31: Optimizar prompts, cachear respuestas, cambiar proveedor
